<?xml version="1.0" ?>

<robot name="robot">
    <!-- Adding plugin to drive robot-->
    <gazebo>
        <plugin filename="libgazebo_ros_diff_drive.so" name="differential_drive_controller">
            <alwaysOn>true</alwaysOn>
            <updateRate>20</updateRate>
            <leftJoint>joint_chassis_left_wheel</leftJoint>
            <rightJoint>joint_chassis_right_wheel</rightJoint>
            <wheelSeparation>1.66</wheelSeparation>
            <wheelDiameter>0.8</wheelDiameter>
            <torque>10</torque>
            <commandTopic>cmd_vel</commandTopic>
            <odometryTopic>odom</odometryTopic>
            <odometryFrame>odom</odometryFrame>
            <robotBaseFrame>link_chassis</robotBaseFrame>
        </plugin>
    </gazebo>
    <!--gazebo script for add material and settiing friction coefficient to Robot -->
    <gazebo reference="link_chassis">
        <material>Gazebo/Blue</material>
    </gazebo>
    <gazebo reference="link_caster_wheel">
        <mu1> 0.2 </mu1>
        <mu2> 0.2 </mu2>
        <material>Gazebo/Grey</material>
    </gazebo>
    <gazebo reference="link_left_wheel">
        <mu1> 0.2 </mu1>
        <mu2> 0.2 </mu2>
        <material>Gazebo/Black</material>
    </gazebo>
    <gazebo reference="link_right_wheel">
        <mu1> 0.2 </mu1>
        <mu2> 0.2 </mu2>
        <material>Gazebo/Black</material>
    </gazebo>
    <!--gazebo script for making joint fixed for friction purpose -->
    <gazebo reference="joint_chassis_caster_wheel">
        <preserveFixedJoint>true</preserveFixedJoint>
    </gazebo>

    <!-- Link - chassis -->
    <link name="link_chassis">
        <inertial>
            <mass value="10" />
            <origin xyz="0 0 0.3" rpy="0 0 0" />
            <inertia ixx="1.5417" ixy="0" ixz="0" iyy="3.467" iyz="0" izz="4.742" />
        </inertial>

        <collision>
            <geometry>
                <box size="2 1.3 0.4" />
            </geometry>
        </collision>

        <visual>
            <geometry>
                <mesh filename="package://robot_description/meshes/chassis.stl" />
            </geometry>
            <material name="Blue">
                <color rgba="0 0 1 1" />
            </material>
        </visual>
    </link>
    <!-- Joint - caster wheel -->
    <joint name="joint_chassis_caster_wheel" type="fixed">
        <origin rpy="0 0 0" xyz="0.8 0 -0.15" />
        <child link="link_caster_wheel" />
        <parent link="link_chassis" />
        <joint_properties damping="1.0" friction="1.0" />
    </joint>
    <!-- Link - caster wheel -->
    <link name="link_caster_wheel">
        <inertial>
            <mass value="1" />
            <origin xyz="0 0 0" rpy="0 0 0" />
            <inertia ixx="0.002526666666667" ixy="0" ixz="0" iyy="0.002526666666667" iyz="0" izz="0.005"/>
        </inertial>

        <!-- Caster wheel support -->
        <collision>
            <origin rpy="0 0 0" xyz="0 0 -0.03" />
            <geometry>
                <sphere radius="0.2" />
            </geometry>
        </collision>
        <visual>
            <origin rpy="0 0 0" xyz="0 0 -0.03" />
            <geometry>
                <sphere radius="0.2" />
            </geometry>
            <material name="DarkBlue">
                <color rgba="0.2 0.2 0.4 1" />
            </material>
        </visual>

        <!-- Caster wheel -->
        <collision>
            <origin rpy="0 0 0" xyz="0 0 -0.15" />
            <geometry>
                <sphere radius="0.10" />
            </geometry>
        </collision>
        <visual>
            <origin rpy="0 0 0" xyz="0 0 -0.15" />
            <geometry>
                <sphere radius="0.10" />
            </geometry>
            <material name="Grey">
                <color rgba="0.6 0.6 0.6 1" />
            </material>
        </visual>
    </link>
    <!-- Joint - chassis / left wheel -->
    <joint name="joint_chassis_left_wheel" type="continuous">
        <origin rpy="0 0 0" xyz="-0.5 0.65 0" />
        <child link="link_left_wheel" />
        <parent link="link_chassis" />
        <axis rpy="0 0 0" xyz="0 1 0" />
        <limit effort="10000" velocity="1000" />
        <joint_properties damping="1.0" friction="1.0" />
    </joint>

    <!-- Link - left wheel -->
    <link name="link_left_wheel">
        <inertial>
            <mass value="1" />
            <origin xyz="0 0 0" rpy="0 0 0" />
            <inertia ixx="0.002526666666667" ixy="0" ixz="0" iyy="0.002526666666667" iyz="0" izz="0.005"/>
        </inertial>

        <collision>
            <origin rpy="1.5707 0 0" xyz="0 0.18 0" />
            <geometry>
                <cylinder length="0.12" radius="0.4"/>
            </geometry>
        </collision>
        <visual>
            <origin rpy="1.5707 0 0" xyz="0 0.18 0" />
            <geometry>
                <mesh filename = "package://robot_description/meshes/wheel.stl"/>
            </geometry>
            <material name="Black">
                <color rgba="0 0 0 1" />
            </material>
        </visual>
        <!-- Link - Axle - Left- wheel-->
        <collision>
            <origin rpy="1.5707 0 0" xyz="0 0.06 0" />
            <geometry>
                <cylinder length="0.18" radius="0.08"/>
            </geometry>
        </collision>
        <visual>
            <origin rpy="1.5707 0 0" xyz="0 0.06 0" />
            <geometry>
                <cylinder length="0.18" radius="0.08"/>
            </geometry>
            <material name="white">
                <color rgba="1 1 1 1" />
            </material>
        </visual>
        <!-- Link - Hubcap - Left- wheel-->
        <visual>
            <origin rpy="1.5707  0 0" xyz="0 0.18 0" />
            <geometry>
                 <box size="0.02 0.5 0.02" />
            </geometry>
            <material name="white">
                <color rgba="1 1 1 1" />
            </material>
        </visual>
    </link>
    <!-- Joint - chassis / right wheel-->
    
    <joint name= "joint_chassis_right_wheel" type = "continuous">
        <origin rpy="0 0 0" xyz="-0.5 -0.65 0" />
        <child link="link_right_wheel" />
        <parent link="link_chassis" />
        <axis rpy="0 0 0" xyz="0 1 0" />
        <limit effort="10000" velocity="1000" />
        <joint_properties damping="1.0" friction="1.0" />
    </joint>
    <!-- Link - Right wheel-->
    <link name = "link_right_wheel">
        <inertial>
            <mass value = "1"/>
            <origin xyz="0 0 0" rpy = "0 0 0"/>
            <inertia ixx ="0.002526666666667" ixy="0" ixz="0" iyy="0.002526666666667" iyz="0" izz="0.005"/>
        </inertial>
        <collision>
            <origin rpy="1.5707 0 0" xyz="0 -0.18 0" />
            <geometry>
                <cylinder length="0.12" radius="0.4"/>
            </geometry>
        </collision>
        <visual>
            <origin rpy="1.5707 0 0" xyz="0 -0.18 0" />
            <geometry>
                <mesh filename = "package://robot_description/meshes/wheel.stl"/>
            </geometry>
            <material name="Black">
                <color rgba="0 0 0 1" />
            </material>
        </visual>
        <!-- Link - Axle - Right- wheel-->
        <collision>
            <origin rpy="1.5707 0 0" xyz="0 -0.06 0" />
            <geometry>
                <cylinder length="0.18" radius="0.08"/>
            </geometry>
        </collision>
        <visual>
            <origin rpy="1.5707 0 0" xyz="0 -0.06 0" />
            <geometry>
                <cylinder length="0.18" radius="0.08"/>
            </geometry>
            <material name="White">
                <color rgba="1 1 1 1" />
            </material>
        </visual>
        <!-- Link - Hubcap - Right wheel-->
        <visual>
            <origin rpy="1.5707  0 0" xyz="0 -0.18 0" />
            <geometry>
                 <box size="0.02 0.5 0.02" />
            </geometry>
            <material name="white">
                <color rgba="1 1 1 1" />
            </material>
        </visual>
    </link>
    <!-- Joint -->
</robot>